Workbook

Sheet Index
B3: Emami Limited - Financial Model Index
B5: Sheet | C5: Description
B6: Index | C6: This Page - model navigation and overview
B7: Assumptions | C7: Company details and key model assumptions
B8: Inputs | C8: Historical financial data (FY2022–FY2026): P&L, Balance Sheet, Cash Flow
B9: Scenarios | C9: Bull, Base, and Bear case revenue assumptions
B10: Model | C10: Historical and forecasted financial statements
B11: Ratio Analysis | C11: Key financial ratios (profitability, liquidity, solvency, efficiency) with interpretations
B12: Equity Beta | C12: Calculation of company beta
B13: Market Returns | C13: Historical market return data for WACC calculation
B14: DCF Valuation | C14: WACC, Unlevered FCFF, Terminal Value, DCF & EV/EBITDA Intrinsic Value calculation
B15: Comps Inputs | C15: Inputs used for Comparable Company Valuation
B16: Comps Valuation | C16: Relative valuation using peer trading multiples
B17: Summary | C17: Executive summary of model outputs

Sheet Assumptions
B4: Company Name | D4: Emami Limited
B5: ISIN Code | D5: INE548C01032
B6: Sector Name | D6: FMCG
B7: Industry | D7: Personal Products
B8: Exchange Name | D8: EMAMILTD
B9: Website | D9: http://www.emamiltd.in
B10: Company Description | D10: Emami Limited is one of India's leading FMCG companies, engaged in the manufacturing, marketing, and distribution of a diverse portfolio of personal care, healthcare, and wellness products. The Company has a strong presence in the beauty, skincare, haircare, men's grooming, and Ayurvedic healthcare segments, with several well-established brands catering to both domestic and international markets. Emami's product portfolio includes brands such as BoroPlus, Navratna, Kesh King, Zandu, Smart And Handsome, and Dermicool.
B11: Current Market Price | D11: 420.05
B15: Company Data
B16: Particulars
B17: No. of Outstanding Shares | C17: Nos in Lacs | D17: 4365
B18: Face Value per share | C18: ₹ | D18: 1
B19: Current Market Price | C19: ₹ | D19: =D11 -> 420.05
B20: Market Capitalization | C20: ₹ in Lacs | D20: =D17*D19 -> 1833518.2
B21: 52 Week Low/High | C21: ₹ | D21: 376.40 - 634.20
B24: Assumptions
B25: Revenue Growth Rate (%) | D25: 0.09
B26: Perpetual Growth Rate (%) | D26: 0.04
B27: 10 year Bond Yield rate (%) | D27: 0.06707
B28: Interest Rate (Pre Tax) (%) | D28: 0.124
B29: Capital Expenditure Growth Rate (%) | D29: 0.005
B33: Particulars | C33: Assumptions
B34: Revenue | C34: Revenue has been projected based on the expected growth outlook of the industry and the company's ability to maintain its market position. FY2027 revenue growth is assumed at 9.0%, in line with CRISIL Ratings' expectation of 8–10% revenue growth for the Indian FMCG sector. Growth is gradually tapered towards the perpetual growth rate over the forecast period. Source: [CRISIL Ratings, May 2026]. Revenue growth gradually declines over the forecast period and converges towards the perpetual growth rate of 4.0% by FY2036.
C35: Bull Case: Assumes stronger-than-expected industry growth, market share gains, successful product expansion, and favorable consumer demand, resulting in growth rates approximately 5% higher than the Base Case.
C36: Bear Case: Assumes weaker industry conditions, increased competitive pressures, or slower consumer demand, resulting in growth rates approximately 5% lower than the Base Case.
B37: Costs | C37: All operating costs excluding finance costs, tax, and depreciation, have been forecasted as a % of total Revenue from Operations using the letest years %
C38: Finance cost has been projected using the company's latest historical effective borrowing rate, calculated based on the most recent financial year's finance cost and outstanding debt balance. The forecast assumes that the company's debt level remains constant throughout the projection period, with no significant new borrowings, repayments, or refinancing activities.
C39: Depreciation expense is forecasted using the historical average depreciation rate observed over the historical period.
C40: Tax expense has been forecasted by increasing the effective tax rate (calculated as a % of PBT) by 0.5% once every 2 years.
B41: Dividend | C41: Dividend payments are forecast based on the historical average dividend payout ratio over the last five years, which is held constant throughout the forecast period.
B42: Working Capital | C42: For working capital forecasting purposes, all revenue is assumed to be generated on credit.
C43: Trade Receivables, Inventory, and Trade Payables are forecast using a days-based methodology. Receivable Days, Inventory Days, and Payable Days are calculated as the average of the historical five-year period (FY2022–FY2026) and are assumed to remain constant throughout the forecast period.
C44: DSO DIO DPO are calculated by assuming 365 days in a year.
B45: Fixed Asset Schedule | C45: Property, Plant & Equipment is rolled forward through the depreciation schedule, where the closing PPE balance each year equals the opening PPE balance plus capital expenditure for the year less depreciation for the year. Capital expenditure for the first forecast year is taken as the average of the last four historical years' capex, and from the following year onward it is grown at a constant rate of 0.5% per year.
B46: Debt | C46: Debt is assumed to remain constant at ₹16,192 Lacs (FY2026 level) for the entire forecast period, with no new borrowings, repayments, or refinancing assumed — this is consistent with the assumption used for projecting finance costs, where the effective borrowing rate is applied to a constant debt balance.
B47: Equity | C47: Equity Share Capital is also held constant ₹4,365 Lacs (FY2026 level), implying no new share issuance or buyback during the forecast period. Retained Earnings (Other Equity) is rolled forward each year as the prior year's Retained Earnings plus Net Earnings for the year less Dividends Paid during the year, consistent with the Dividend Payout Ratio assumption used in the income statement.
B48: Balance Sheet | C48: All Balance Sheet items, except Property, Plant & Equipment (PPE), Trade Receivables, Inventory, Trade Payables, Borrowings (Current and Non-Current), Equity, and Cash & Cash Equivalents, are assumed to remain constant at their FY2026 balances throughout the forecast period.
C49: Cash and Cash equivalents are taken as the balancing figures in the Balance Sheet.
B51: Football Field Analysis: Data Sources
B52: Market Consensus | C52: Data Source : Market Screener analyst consensus (July 2026)

Sheet Inputs
A1: Emami Limited
A2: Historical Financial Information
B4: Financial Statement | H4: 2022 | I4: =H4+1 -> 2023 | J4: =I4+1 -> 2024 | K4: =J4+1 -> 2025 | L4: 2026
B5: Income Statement
C6: INCOME
D7: Revenue from Operations | F7: ₹ in Lacs | H7: 318722.28 | I7: 340573.01 | J7: 357809.46 | K7: 380918.86 | L7: 377951
D8: Other Income | F8: ₹ in Lacs | H8: 9525 | I8: 6893.16 | J8: 4679.78 | K8: 6811.39 | L8: 8511
D9: Total Income | F9: ₹ in Lacs | H9: =SUM(H7:H8) -> 328247.28 | I9: =SUM(I7:I8) -> 347466.17 | J9: =SUM(J7:J8) -> 362489.24 | K9: =SUM(K7:K8) -> 387730.25 | L9: =SUM(L7:L8) -> 386462
C10: EXPENSES
D11: Cost of Materials Consumed | F11: ₹ in Lacs | H11: 89549.4 | I11: 82473.89 | J11: 76883.75 | K11: 72413.06 | L11: 75606
D12: Purchases of Stock-in-Trade | F12: ₹ in Lacs | H12: 22346.64 | I12: 33968.83 | J12: 40722.79 | K12: 44832.34 | L12: 43841
D13: Decrease/(Increase) in Inventories of Finished Goods, Stock in trade and Work-in-Progress | F13: ₹ in Lacs | H13: -4589.4 | I13: 3693.34 | J13: -1553.16 | K13: 2177.99 | L13: -5646
D14: Employee Benefits Expense | F14: ₹ in Lacs | H14: 31777.29 | I14: 36776.14 | J14: 39563.89 | K14: 44701.86 | L14: 47909
D15: Other Expenses | F15: ₹ in Lacs | H15: 84400.86 | I15: 97385.29 | J15: 107238.48 | K15: 114282.61 | L15: 119876
D16: Total Expenses before Exceptional items, Interest, Depreciation & Amortisation and Tax | F16: ₹ in Lacs | H16: =SUM(H11:H15) -> 223484.79 | I16: =SUM(I11:I15) -> 254297.49 | J16: =SUM(J11:J15) -> 262855.75 | K16: =SUM(K11:K15) -> 278407.86 | L16: =SUM(L11:L15) -> 281586
D17: Earnings before Share of loss of Associates, Exceptional Items, Interest, Depreciation & Amortisation and Tax | F17: ₹ in Lacs | H17: =H9-H16 -> 104762.49 | I17: =I9-I16 -> 93168.68 | J17: =J9-J16 -> 99633.49 | K17: =K9-K16 -> 109322.39 | L17: =L9-L16 -> 104876
D18: Finance Costs | F18: ₹ in Lacs | H18: 507.29 | I18: 739.14 | J18: 997.72 | K18: 933.69 | L18: 1113
D19: Depreciation & Amortisation Expense :
D20: a) Amortisation of Intangible Assets | F20: ₹ in Lacs | H20: 24056.67 | I20: 14989.2 | J20: 9318.47 | K20: 9255.35 | L20: 8845
D21: b) Depreciation of Property, Plant & Equipment | F21: ₹ in Lacs | H21: 8682.38 | I21: 8768.92 | J21: 7863.19 | K21: 7045.96 | L21: 7065
D22: c) Depreciation of Right of Use Assets | F22: ₹ in Lacs | H22: 738.74 | I22: 966.78 | J22: 1408.93 | K22: 1520.09 | L22: 1824
D23: Total Expenses before Exceptional items and Tax | F23: ₹ in Lacs | H23: =H16+H18+(SUM(H20:H22)) -> 257469.87 | I23: =I16+I18+(SUM(I20:I22)) -> 279761.53 | J23: =J16+J18+(SUM(J20:J22)) -> 282444.06 | K23: =K16+K18+(SUM(K20:K22)) -> 297162.95 | L23: =L16+L18+(SUM(L20:L22)) -> 300433
D24: Share of loss of Associates | F24: ₹ in Lacs | H24: -1458.42 | I24: -749.7 | J24: -372.36 | K24: -1181.02 | L24: -407
D25: Profit Before Exceptional Items and Tax | F25: ₹ in Lacs | H25: =H9-H23+H24 -> 69318.99 | I25: =I9-I23+I24 -> 66954.94 | J25: =J9-J23+J24 -> 79672.82 | K25: =K9-K23+K24 -> 89386.28 | L25: =L9-L23+L24 -> 85622
D26: Exceptional Items | F26: ₹ in Lacs | H26: -518.49 | I26: 0 | J26: -589.54 | K26: - | L26: -1015
D27: Profit Before Tax | F27: ₹ in Lacs | H27: =SUM(H25:H26) -> 68800.5 | I27: =SUM(I25:I26) -> 66954.94 | J27: =SUM(J25:J26) -> 79083.28 | K27: =SUM(K25:K26) -> 89386.28 | L27: =SUM(L25:L26) -> 84607
D28: Tax Expense: | F28: ₹ in Lacs
D29: Current Tax (Including MAT) | F29: ₹ in Lacs | H29: 13538.71 | I29: 12677.73 | J29: 14465.25 | K29: 17872.25 | L29: 17296
D30: MAT Credit Entitlement | F30: ₹ in Lacs | H30: -5775.55 | I30: -8554 | J30: -7667.66 | K30: -8391 | L30: -8416
D31: MAT Credit Entitlement for earlier years | F31: ₹ in Lacs | H31: -23033 | I31: - | J31: - | K31: - | L31: 0
D32: Deferred Tax Charge / (Credit) | F32: ₹ in Lacs | H32: 403.84 | I32: 90.06 | J32: -127.91 | K32: -369.43 | L32: -1799
D33: Total tax expense | F33: ₹ in Lacs | H33: =SUM(H29:H32) -> -14866 | I33: =SUM(I29:I32) -> 4213.79 | J33: =SUM(J29:J32) -> 6669.68 | K33: =SUM(K29:K32) -> 9111.82 | L33: =SUM(L29:L32) -> 7081
D34: Profit for the year | F34: ₹ in Lacs | H34: =H27-H33 -> 83666.5 | I34: =I27-I33 -> 62741.15 | J34: =J27-J33 -> 72413.6 | K34: =K27-K33 -> 80274.46 | L34: =L27-L33 -> 77526
B38: Balance Sheet
C39: ASSETS
D40: 1. Non-Current Assets
D41: (a) Property, Plant and Equipment | F41: ₹ in Lacs | H41: 68569.04 | I41: 63005.53 | J41: 58114.73 | K41: 54454.75 | L41: 52924
D42: (b) Capital Work-in-Progress | F42: ₹ in Lacs | H42: 172.3 | I42: 575.3 | J42: 672.49 | K42: 1327.55 | L42: 79
D43: (c) Investment Property | F43: ₹ in Lacs | H43: 5412.69 | I43: 5338.9 | J43: 5198.57 | K43: 5108.09 | L43: 4007
D44: (d) Goodwill on Consolidation | F44: ₹ in Lacs | H44: 2415.35 | I44: 6819 | J44: 6819 | K44: 6819 | L44: 6819
...

Sheet Scenarios
A1: Emami Limited
A2: Scenarios
C7: Scenarios | E7: Growth % | H7: 2027 | I7: =H7+1 -> 2028 | J7: =I7+1 -> 2029 | K7: =J7+1 -> 2030 | L7: =K7+1 -> 2031 | M7: =L7+1 -> 2032 | N7: =M7+1 -> 2033 | O7: =N7+1 -> 2034 | P7: =O7+1 -> 2035 | Q7: =P7+1 -> 2036
D8: Base Case | E8: 0.09 | H8: =E8 -> 0.09 | I8: =H8*(1-$E$11) -> 0.08235 | J8: =I8*(1-$E$11) -> 0.07535025 | K8: =J8*(1-$E$11) -> 0.068945479 | L8: =K8*(1-$E$11) -> 0.063085113 | M8: =L8*(1-$E$11) -> 0.057722878 | N8: =M8*(1-$E$11) -> 0.052816434 | O8: =N8*(1-$E$11) -> 0.048327037 | P8: =O8*(1-$E$11) -> 0.044219239 | Q8: =P8*(1-$E$11) -> 0.040460603
D9: Bull Case | E9: =E8+5% -> 0.14 | H9: =E9 -> 0.14 | I9: =H9*(1-$E$11) -> 0.1281 | J9: =I9*(1-$E$11) -> 0.1172115 | K9: =J9*(1-$E$11) -> 0.10724852 | L9: =K9*(1-$E$11) -> 0.098132398 | M9: =L9*(1-$E$11) -> 0.089791144 | N9: =M9*(1-$E$11) -> 0.082158897 | O9: =N9*(1-$E$11) -> 0.075175391 | P9: =O9*(1-$E$11) -> 0.068785483 | Q9: =P9*(1-$E$11) -> 0.062938717
D10: Bear Case | E10: =E8-5% -> 0.04 | H10: =E10 -> 0.04 | I10: =H10*(1-$E$11) -> 0.0366 | J10: =I10*(1-$E$11) -> 0.033489 | K10: =J10*(1-$E$11) -> 0.030642435 | L10: =K10*(1-$E$11) -> 0.028037828 | M10: =L10*(1-$E$11) -> 0.025654613 | N10: =M10*(1-$E$11) -> 0.023473971 | O10: =N10*(1-$E$11) -> 0.021478683 | P10: =O10*(1-$E$11) -> 0.019652995 | Q10: =P10*(1-$E$11) -> 0.01798249
D11: Annual Growth Tapering | E11: 0.085

Sheet Model
A1: Emami Limited
A2: Financial Statements & DCF Analysis | H2: 2022 | I2: =H2+1 -> 2023 | J2: =I2+1 -> 2024 | K2: =J2+1 -> 2025 | L2: 2026 | M2: =L2+1 -> 2027 | N2: =M2+1 -> 2028 | O2: =N2+1 -> 2029 | P2: =O2+1 -> 2030 | Q2: =P2+1 -> 2031 | R2: =Q2+1 -> 2032 | S2: =R2+1 -> 2033 | T2: =S2+1 -> 2034 | ... V2: =U2+1 -> 2036
D3: Master Check | H3: =IF(ABS(H79)>0,"Error","Ok") -> Ok | I3: =IF(ABS(I79)>0,"Error","Ok") -> Ok | J3: =IF(ABS(J79)>0,"Error","Ok") -> Ok | K3: =IF(ABS(K79)>0,"Error","Ok") -> Ok | L3: =IF(ABS(L79)>0,"Error","Ok") -> Ok | M3: =IF(ABS(M79)>0,"Error","Ok") -> Ok | N3: =IF(ABS(N79)>0,"Error","Ok") -> Ok | O3: =IF(ABS(O79)>0,"Error","Ok") -> Ok | ... V3: =IF(ABS(V79)>0,"Error","Ok") -> Ok
A5: Ratios and Assumptions
D7: SCENARIO | E7: Base Case | F7: Units | G7: =IF(E7=Scenarios!D8,1,IF(Model!E7=Scenarios!D9,2,3)) -> 1
D8: Revenue Growth | F8: % | I8: =I26/H26-1 -> 0.068557272 | J8: =J26/I26-1 -> 0.050610147 | K8: =K26/J26-1 -> 0.064585771 | L8: =L26/K26-1 -> -0.0077913181 | M8: {=CHOOSE(G7,Scenarios!H8:Q8,Scenarios!H9:Q9,Scenarios!H10:Q10)} -> 0.09 | N8: 0.08235 | O8: 0.07535025 | P8: 0.068945479 | Q8: 0.063085113 | R8: 0.057722878 | S8: 0.052816434 | T8: 0.048327037 | U8: 0.044219239 | V8: 0.040460603
D9: COGS (% of Revenue) | F9: % | H9: =-H27/H26 -> 0.33667756 | I9: =-I27/I26 -> 0.35274686 | J9: =-J27/J26 -> 0.32434408 | K9: =-K27/K26 -> 0.31351399 | L9: =-L27/L26 -> 0.30109988 | M9: =AVERAGE(H9:L9) -> 0.32567647 | N9: =M9 -> 0.32567647 | O9: =N9 -> 0.32567647 | P9: =O9 -> 0.32567647 | Q9: =P9 -> 0.32567647 | R9: =Q9 -> 0.32567647 | S9: =R9 -> 0.32567647 | T9: =S9 -> 0.32567647 | U9: =T9 -> 0.32567647 | V9: =U9 -> 0.32567647
D10: Salaries and Benefits (% of Revenue) | F10: % | H10: =-H30/H26 -> 0.099702129 | I10: =-I30/I26 -> 0.10798313 | J10: =-J30/J26 -> 0.11057251 | K10: =-K30/K26 -> 0.11735271 | L10: =-L30/L26 -> 0.12675982 | M10: =AVERAGE(H10:L10) -> 0.11247406 | N10: =M10 -> 0.11247406 | O10: =N10 -> 0.11247406 | P10: =O10 -> 0.11247406 | Q10: =P10 -> 0.11247406 | R10: =Q10 -> 0.11247406 | S10: =R10 -> 0.11247406 | T10: =S10 -> 0.11247406 | U10: =T10 -> 0.11247406 | V10: =U10 -> 0.11247406
D11: Other SG&A Expense (% of Revenue) | F11: % | H11: =-H31/H26 -> 0.26481004 | I11: =-I31/I26 -> 0.28594541 | J11: =-J31/J26 -> 0.29970834 | K11: =-K31/K26 -> 0.30001825 | L11: =-L31/L26 -> 0.31717339 | M11: =AVERAGE(H11:L11) -> 0.29353109 | N11: =M11 -> 0.29353109 | O11: =N11 -> 0.29353109 | P11: =O11 -> 0.29353109 | Q11: =P11 -> 0.29353109 | R11: =Q11 -> 0.29353109 | S11: =R11 -> 0.29353109 | T11: =S11 -> 0.29353109 | U11: =T11 -> 0.29353109 | V11: =U11 -> 0.29353109
D12: Depreciation and Amortisation (% of PPE) | F12: % | I12: =-I33/I128 -> 0.34959188 | J12: =-J33/J128 -> 0.2841387 | K12: =-K33/K128 -> 0.2888616 | L12: =-L33/L128 -> 0.30254311 | M12: =AVERAGE(I12:L12) -> 0.30628382 | N12: =M12 -> 0.30628382 | O12: =N12 -> 0.30628382 | P12: =O12 -> 0.30628382 | Q12: =P12 -> 0.30628382 | R12: =Q12 -> 0.30628382 | S12: =R12 -> 0.30628382 | T12: =S12 -> 0.30628382 | U12: =T12 -> 0.30628382 | V12: =U12 -> 0.30628382
D13: Interest Expense (% of Debt) | F13: % | I13: =-I35/I135 -> 0.026252027 | J13: =-J35/J135 -> 0.11023556 | K13: =-K35/K135 -> 0.099375345 | L13: =-L35/L135 -> 0.12395465 | M13: =L13 -> 0.12395465 | N13: =M13 -> 0.12395465 | O13: =N13 -> 0.12395465 | P13: =O13 -> 0.12395465 | Q13: =P13 -> 0.12395465 | R13: =Q13 -> 0.12395465 | S13: =R13 -> 0.12395465 | T13: =S13 -> 0.12395465 | ... V13: =U13 -> 0.12395465
D14: Other Income/(Expenses) (% of Revenue) | F14: % | H14: =H36/H26 -> 0.023682342 | I14: =I36/I26 -> 0.018038599 | J14: =J36/J26 -> 0.01039067 | K14: =K36/K26 -> 0.014781022 | L14: =L36/L26 -> 0.0187564 | M14: =AVERAGE(H14:L14) -> 0.017129806 | N14: =M14 -> 0.017129806 | O14: =N14 -> 0.017129806 | P14: =O14 -> 0.017129806 | Q14: =P14 -> 0.017129806 | R14: =Q14 -> 0.017129806 | S14: =R14 -> 0.017129806 | T14: =S14 -> 0.017129806 | U14: =T14 -> 0.017129806 | V14: =U14 -> 0.017129806
D15: Taxes (% of EBT) | F15: % | H15: =H38/H37 -> 0.21607401 | I15: =-I38/I37 -> 0.062934714 | J15: =-J38/J37 -> 0.084337423 | K15: =-K38/K37 -> 0.10193757 | L15: =-L38/L37 -> 0.083692839 | M15: =L15+0.5% -> 0.088692839 | N15: =M15 -> 0.088692839 | O15: =N15+0.5% -> 0.093692839 | P15: =O15 -> 0.093692839 | Q15: =P15+0.5% -> 0.098692839 | R15: =Q15 -> 0.098692839 | S15: =R15+0.5% -> 0.10369284 | T15: =S15 -> 0.10369284 | U15: =T15+0.5% -> 0.10869284 | V15: =U15 -> 0.10869284
D16: Dividend Payout Ratio | F16: % | H16: =-H104/H39 -> 0.42503391 | I16: =-I104/I39 -> 0.56250164 | J16: =-J104/J39 -> 0.48222986 | K16: =-K104/K39 -> 0.4350076 | L16: =-L104/L39 -> 0.6756443 | M16: =AVERAGE(H16:L16) -> 0.51608346 | N16: =M16 -> 0.51608346 | O16: =N16 -> 0.51608346 | P16: =O16 -> 0.51608346 | Q16: =P16 -> 0.51608346 | R16: =Q16 -> 0.51608346 | S16: =R16 -> 0.51608346 | T16: =S16 -> 0.51608346 | U16: =T16 -> 0.51608346 | V16: =U16 -> 0.51608346
D17: Accounts Receivable | F17: Days | H17: =H49/H26*365 -> 36.751533 | I17: =I49/I26*365 -> 44.43403 | J17: =J49/J26*365 -> 50.414644 | K17: =K49/K26*365 -> 43.243459 | L17: =L49/L26*365 -> 33.155568 | M17: =AVERAGE(H17:L17) -> 41.599847 | N17: =M17 -> 41.599847 | O17: =N17 -> 41.599847 | P17: =O17 -> 41.599847 | Q17: =P17 -> 41.599847 | R17: =Q17 -> 41.599847 | S17: =R17 -> 41.599847 | T17: =S17 -> 41.599847 | U17: =T17 -> 41.599847 | V17: =U17 -> 41.599847
D18: Inventory | F18: Days | H18: =H50/-H27*365 -> 121.64133 | I18: =I50/-I27*365 -> 99.665616 | J18: =J50/-J27*365 -> 101.71309 | K18: =K50/-K27*365 -> 94.167021 | L18: =L50/-L27*365 -> 128.15621 | M18: =AVERAGE(H18:L18) -> 109.06865 | N18: =M18 -> 109.06865 | O18: =N18 -> 109.06865 | P18: =O18 -> 109.06865 | Q18: =P18 -> 109.06865 | R18: =Q18 -> 109.06865 | S18: =R18 -> 109.06865 | T18: =S18 -> 109.06865 | U18: =T18 -> 109.06865 | V18: =U18 -> 109.06865
D19: Accounts Payable | F19: Days | H19: =H65/-H27*365 -> 139.02969 | I19: =I65/-I27*365 -> 126.47978 | J19: =J65/-J27*365 -> 142.97261 | K19: =K65/-K27*365 -> 133.13445 | L19: =L65/-L27*365 -> 153.00999 | M19: =AVERAGE(H19:L19) -> 138.9253 | N19: =M19 -> 138.9253 | O19: =N19 -> 138.9253 | P19: =O19 -> 138.9253 | Q19: =P19 -> 138.9253 | R19: =Q19 -> 138.9253 | S19: =R19 -> 138.9253 | T19: =S19 -> 138.9253 | U19: =T19 -> 138.9253 | V19: =U19 -> 138.9253
D20: Capital Asset Turnover Ratio | F20: Times | H20: =H26/H55 -> 4.5064984 | I20: =I26/I55 -> 5.2053201 | J20: =J26/J55 -> 5.7996236 | K20: =K26/K55 -> 6.4984987 | L20: =L26/L55 -> 6.6054563 | M20: =L20+0.05 -> 6.6554563 | N20: =M20+0.05 -> 6.7054563 | O20: =N20+0.05 -> 6.7554563 | P20: =O20+0.05 -> 6.8054563 | Q20: =P20+0.05 -> 6.8554563 | R20: =Q20+0.05 -> 6.9054563 | S20: =R20+0.05 -> 6.9554563 | T20: =S20+0.05 -> 7.0054563 | ... V20: =U20+0.05 -> 7.1054563
A24: Income Statement
C25: INCOME
D26: Revenue | F26: ₹ in Lacs | H26: =Inputs!H7 -> 318722.28 | I26: =Inputs!I7 -> 340573.01 | J26: =Inputs!J7 -> 357809.46 | K26: =Inputs!K7 -> 380918.86 | L26: =Inputs!L7 -> 377951 | M26: =L26*(1+M8) -> 411966.59 | N26: =M26*(1+N8) -> 445892.04 | O26: =N26*(1+O8) -> 479490.12 | P26: =O26*(1+P8) -> 512548.79 | Q26: =P26*(1+Q8) -> 544882.99 | R26: =Q26*(1+R8) -> 576335.2 | S26: =R26*(1+S8) -> 606775.17 | T26: =S26*(1+T8) -> 636098.82 | ... V26: =U26*(1+V8) -> 691101.64
D27: Cost of Goods Sold | F27: ₹ in Lacs | H27: =-SUM(Inputs!H11:H13) -> -107306.64 | I27: =-SUM(Inputs!I11:I13) -> -120136.06 | J27: =-SUM(Inputs!J11:J13) -> -116053.38 | K27: =-SUM(Inputs!K11:K13) -> -119423.39 | L27: =-SUM(Inputs!L11:L13) -> -113801 | M27: =-M26*M9 -> -134167.83 | N27: =-N26*N9 -> -145216.55 | O27: =-O26*O9 -> -156158.65 | P27: =-P26*P9 -> -166925.08 | Q27: =-Q26*Q9 -> -177455.57 | R27: =-R26*R9 -> -187698.82 | S27: =-S26*S9 -> -197612.4 | T27: =-T26*T9 -> -207162.42 | ... V27: =-V26*V9 -> -225075.54
D28: Gross Profit | F28: ₹ in Lacs | H28: =SUM(H26:H27) -> 211415.64 | I28: =SUM(I26:I27) -> 220436.95 | J28: =SUM(J26:J27) -> 241756.08 | K28: =SUM(K26:K27) -> 261495.47 | L28: =SUM(L26:L27) -> 264150 | M28: =SUM(M26:M27) -> 277798.76 | N28: =SUM(N26:N27) -> 300675.49 | O28: =SUM(O26:O27) -> 323331.47 | ... V28: =SUM(V26:V27) -> 466026.09
C29: EXPENSES
D30: Salaries and Benefits | F30: ₹ in Lacs | H30: =-Inputs!H14 -> -31777.29 | I30: =-Inputs!I14 -> -36776.14 | J30: =-Inputs!J14 -> -39563.89 | K30: =-Inputs!K14 -> -44701.86 | L30: =-Inputs!L14 -> -47909 | M30: =-M26*M10 -> -46335.555 | N30: =-N26*N10 -> -50151.288 | O30: =-O26*O10 -> -53930.2 | P30: =-P26*P10 -> -57648.443 | Q30: =-Q26*Q10 -> -61285.202 | R30: =-R26*R10 -> -64822.76 | S30: =-S26*S10 -> -68246.467 | T30: =-T26*T10 -> -71544.616 | ... V30: =-V26*V10 -> -77731.006
D31: Other SG&A Expenses | F31: ₹ in Lacs | H31: =-Inputs!H15 -> -84400.86 | I31: =-Inputs!I15 -> -97385.29 | J31: =-Inputs!J15 -> -107238.48 | K31: =-Inputs!K15 -> -114282.61 | L31: =-Inputs!L15 -> -119876 | M31: =-M26*M11 -> -120925 | N31: =-N26*N11 -> -130883.17 | O31: =-O26*O11 -> -140745.25 | P31: =-P26*P11 -> -150449 | Q31: =-Q26*Q11 -> -159940.1 | R31: =-R26*R11 -> -169172.3 | S31: =-S26*S11 -> -178107.38 | T31: =-T26*T11 -> -186714.78 | ... V31: =-V26*V11 -> -202859.81
D32: EBITDA | F32: ₹ in Lacs | H32: =SUM(H28:H31) -> 95237.49 | I32: =SUM(I28:I31) -> 86275.52 | J32: =SUM(J28:J31) -> 94953.71 | K32: =SUM(K28:K31) -> 102511 | L32: =SUM(L28:L31) -> 96365 | M32: =SUM(M28:M31) -> 110538.21 | N32: =SUM(N28:N31) -> 119641.03 | O32: =SUM(O28:O31) -> 128656.01 | ... V32: =SUM(V28:V31) -> 185435.27
D33: Depreciation & Amortisation Expenses | F33: ₹ in Lacs | H33: =-SUM(Inputs!H20:H22) -> -33477.79 | I33: =-SUM(Inputs!I20:I22) -> -24724.9 | J33: =-SUM(Inputs!J20:J22) -> -18590.59 | K33: =-SUM(Inputs!K20:K22) -> -17821.4 | L33: =-SUM(Inputs!L20:L22) -> -17734 | M33: =M130 -> -17524.948 | N33: =N130 -> -17162.312 | O33: =O130 -> -16935.771 | P33: =P130 -> -16803.766 | Q33: =Q130 -> -16737.467 | R33: =R130 -> -16716.877 | S33: =S130 -> -16728.122 | T33: =T130 -> -16761.58 | ... V33: =V130 -> -16870.478
D34: EBIT | F34: ₹ in Lacs | H34: =SUM(H32:H33) -> 61759.7 | I34: =SUM(I32:I33) -> 61550.62 | J34: =SUM(J32:J33) -> 76363.12 | K34: =SUM(K32:K33) -> 84689.6 | L34: =SUM(L32:L33) -> 78631 | M34: =SUM(M32:M33) -> 93013.26 | N34: =SUM(N32:N33) -> 102478.72 | O34: =SUM(O32:O33) -> 111720.24 | ... V34: =SUM(V32:V33) -> 168564.79
D35: Interest Expense | F35: ₹ in Lacs | H35: =-Inputs!H18 -> -507.29 | I35: =-Inputs!I18 -> -739.14 | J35: =-Inputs!J18 -> -997.72 | K35: =-Inputs!K18 -> -933.69 | L35: =-Inputs!L18 -> -1113 | M35: =M138 -> -2007.0738 | N35: =N138 -> -2007.0738 | O35: =O138 -> -2007.0738 | P35: =P138 -> -2007.0738 | Q35: =Q138 -> -2007.0738 | R35: =R138 -> -2007.0738 | S35: =S138 -> -2007.0738 | T35: =T138 -> -2007.0738 | ... V35: =V138 -> -2007.0738
D36: Other Income (Expenses) | F36: ₹ in Lacs | H36: =SUM(Inputs!H8,Inputs!H26,Inputs!H24) -> 7548.09 | I36: =SUM(Inputs!I8,Inputs!I26,Inputs!I24) -> 6143.46 | J36: =SUM(Inputs!J8,Inputs!J26,Inputs!J24) -> 3717.88 | K36: =SUM(Inputs!K8,Inputs!K26,Inputs!K24) -> 5630.37 | L36: =SUM(Inputs!L8,Inputs!L26,Inputs!L24) -> 7089 | M36: =M26*M14 -> 7056.908 | N36: =N26*N14 -> 7638.0443 | O36: =O26*O14 -> 8213.5729 | P36: =P26*P14 -> 8779.8616 | Q36: =Q26*Q14 -> 9333.7402 | R36: =R26*R14 -> 9872.5105 | S36: =S26*S14 -> 10393.941 | T36: =T26*T14 -> 10896.25 | ... V36: =V26*V14 -> 11838.437
D37: Earnings Before Taxes | F37: ₹ in Lacs | H37: =SUM(H34:H36) -> 68800.5 | I37: =SUM(I34:I36) -> 66954.94 | J37: =SUM(J34:J36) -> 79083.28 | K37: =SUM(K34:K36) -> 89386.28 | L37: =SUM(L34:L36) -> 84607 | M37: =SUM(M34:M36) -> 98063.095 | N37: =SUM(N34:N36) -> 108109.69 | O37: =SUM(O34:O36) -> 117926.74 | ... V37: =SUM(V34:V36) -> 178396.16
D38: Taxes | F38: ₹ in Lacs | H38: =-Inputs!H33 -> 14866 | I38: =-Inputs!I33 -> -4213.79 | J38: =-Inputs!J33 -> -6669.68 | K38: =-Inputs!K33 -> -9111.82 | L38: =-Inputs!L33 -> -7081 | M38: =-M37*M15 -> -8697.4942 | N38: =-N37*N15 -> -9588.5551 | O38: =-O37*O15 -> -11048.891 | P38: =-P37*P15 -> -11945.395 | Q38: =-Q37*Q15 -> -13500.324 | R38: =-R37*R15 -> -14388.418 | S38: =-S37*S15 -> -16017.192 | T38: =-T37*T15 -> -16881.671 | ... V38: =-V37*V15 -> -19390.385
D39: Net Earnings | F39: ₹ in Lacs | H39: =SUM(H37:H38) -> 83666.5 | I39: =SUM(I37:I38) -> 62741.15 | J39: =SUM(J37:J38) -> 72413.6 | K39: =SUM(K37:K38) -> 80274.46 | L39: =SUM(L37:L38) -> 77526 | M39: =SUM(M37:M38) -> 89365.6 | N39: =SUM(N37:N38) -> 98521.133 | O39: =SUM(O37:O38) -> 106877.85 | ... V39: =SUM(V37:V38) -> 159005.77
A43: Balance Sheet
B45: ASSETS
C46: Current Assets
D47: Cash & Cash Equivalents | F47: ₹ in Lacs | H47: =H113 -> 2757.29 | I47: =I113 -> 4678.5 | J47: =J113 -> 5295.39 | K47: =K113 -> 10462.51 | L47: =L113 -> 17675 | M47: =M113 -> 52709.546 | N47: =N113 -> 98162.413 | O47: =O113 -> 147379.17 | ... V47: =V113 -> 595847.61
D48: Bank Deposits | F48: ₹ in Lacs | H48: =Inputs!H63 -> 8843.07 | I48: =Inputs!I63 -> 13795.57 | J48: =Inputs!J63 -> 14842.62 | K48: =Inputs!K63 -> 16827.5 | L48: =Inputs!L63 -> 23309 | M48: =L48 -> 23309 | N48: =M48 -> 23309 | O48: =N48 -> 23309 | P48: =O48 -> 23309 | Q48: =P48 -> 23309 | R48: =Q48 -> 23309 | S48: =R48 -> 23309 | T48: =S48 -> 23309 | ... V48: =U48 -> 23309
D49: Accounts Receivables | F49: ₹ in Lacs | H49: =Inputs!H61 -> 32091.87 | I49: =Inputs!I61 -> 41460.36 | J49: =Inputs!J61 -> 49421.47 | K49: =Inputs!K61 -> 45129.45 | L49: =Inputs!L61 -> 34332 | M49: =M26*M17/365 -> 46952.732 | N49: =N26*N17/365 -> 50819.289 | O49: =O26*O17/365 -> 54648.535 | P49: =P26*P17/365 -> 58416.305 | Q49: =Q26*Q17/365 -> 62101.504 | R49: =R26*R17/365 -> 65686.182 | S49: =S26*S17/365 -> 69155.491 | T49: =T26*T17/365 -> 72497.571 | ... V49: =V26*V17/365 -> 78766.362
...

Sheet Ratio Analysis
A1: Emami Limited
A2: Ratio Analysis
B4: Particulars | C4: 2022 | D4: =C4+1 -> 2023 | E4: =D4+1 -> 2024 | F4: =E4+1 -> 2025 | G4: 2026 | H4: =G4+1 -> 2027 | I4: =H4+1 -> 2028 | J4: =I4+1 -> 2029 | K4: =J4+1 -> 2030 | L4: =K4+1 -> 2031 | M4: =L4+1 -> 2032 | N4: =M4+1 -> 2033 | O4: =N4+1 -> 2034 | ... Q4: =P4+1 -> 2036 | R4: Trend | T4: Interpretation of Ratios
B5: Profitability Ratios
B7: Gross Margin | C7: =Model!H28/Model!H26 -> 0.66332244 | D7: =Model!I28/Model!I26 -> 0.64725314 | E7: =Model!J28/Model!J26 -> 0.67565592 | F7: =Model!K28/Model!K26 -> 0.68648601 | G7: =Model!L28/Model!L26 -> 0.69890012 | H7: =Model!M28/Model!M26 -> 0.67432353 | I7: =Model!N28/Model!N26 -> 0.67432353 | J7: =Model!O28/Model!O26 -> 0.67432353 | ... Q7: =Model!V28/Model!V26 -> 0.67432353 | T7: The Gross Margin drop from 66.33% in FY2022 to 64.73% in FY2023 indicating higher input costs or a less favourable product mix during the year, and then rising consistently to 67.57%, then 68.65% and then finally reaching five year high of 69.89% in FY2026, reflecting improved pricing, better product mix and cost efficiencies. For the forecast period, the margin is held constant at 67.43% as per the projection methodology (COGS projected as a fixed % of Revenue, the five year historical average) indicating a stable, sustainable cost structure going forward.
B8: EBITDA Margin | C8: =Model!H32/Model!H26 -> 0.29881027 | D8: =Model!I32/Model!I26 -> 0.2533246 | E8: =Model!J32/Model!J26 -> 0.26537507 | F8: =Model!K32/Model!K26 -> 0.26911506 | G8: =Model!L32/Model!L26 -> 0.25496691 | H8: =Model!M32/Model!M26 -> 0.26831838 | I8: =Model!N32/Model!N26 -> 0.26831838 | J8: =Model!O32/Model!O26 -> 0.26831838 | ... Q8: =Model!V32/Model!V26 -> 0.26831838 | T8: EBITDA Margin fell sharply from 29.88% in FY2022 to 25.33% in FY2023, as Emami chose to defend and grow market share by increasing advertising and promotion (A&P) spend and employee costs, then it recovered to 26.91% in 2025 and again fell to 25.50% in FY2026, as Salaries & Benefits and Other SG&A Expenses grew at a faster pace than Revenue during this period. From FY2027 onwards, the margin stabilises at a constant 26.83%, since operating expenses are projected as a fixed percentage of Revenue, reflecting an assumption that the company's current cost structure remains sustainable through the forecast horizon.
B9: Operating Margin | C9: =Model!H34/Model!H26 -> 0.19377277 | D9: =Model!I34/Model!I26 -> 0.18072665 | E9: =Model!J34/Model!J26 -> 0.21341839 | F9: =Model!K34/Model!K26 -> 0.22232976 | G9: =Model!L34/Model!L26 -> 0.20804549 | H9: =Model!M34/Model!M26 -> 0.22577865 | I9: =Model!N34/Model!N26 -> 0.22982854 | J9: =Model!O34/Model!O26 -> 0.232998 | ... Q9: =Model!V34/Model!V26 -> 0.24390739 | T9: Operating Margin declined from 19.38% in FY2022 to 18.07% in FY2023 due to higher Depreciation & Amortisation (D&A) eating into EBITDA, then rising to 21.34% in FY2024 and 22.23% in FY2025 because depreciation charges as a percentage of revenue declined as older PPE assets aged and partially written down. In FY2026 in dipped again to 20.80%. From FY2027, the margin rises steadily every year, reaching 24.39% by FY2036 even while the EBITDA margin stays perfectly flat at 26.83%. This consistent expansion is because D&A is projected as a percentage of average Fixed Assets, and since Fixed Asset growth is modest relative to Revenue growth (supported by the rising Fixed Asset Turnover), D&A as a % of Revenue keeps falling, lifting EBIT margin year after year.
B10: Pretax Profit Margin | C10: =Model!H37/Model!H26 -> 0.21586348 | D10: =Model!I37/Model!I26 -> 0.19659497 | E10: =Model!J37/Model!J26 -> 0.22102065 | F10: =Model!K37/Model!K26 -> 0.23465963 | G10: =Model!L37/Model!L26 -> 0.22385706 | H10: =Model!M37/Model!M26 -> 0.23803652 | I10: =Model!N37/Model!N26 -> 0.24245709 | J10: =Model!O37/Model!O26 -> 0.24594196 | ... Q10: =Model!V37/Model!V26 -> 0.25813303 | T10: Pretax Profit Margin moved from 21.59% in FY2022 down to 19.66% in FY2023 (tracking the dip in operating margin), recovered to 23.47% in FY2025, and eased to 22.39% in FY2026. From FY2027 onwards it increases consistently to 25.81% by FY2036. This sustained improvement is driven by two effects acting in the same direction: (a) the rising Operating Margin discussed above, and (b) Interest Expense, which is projected as a percentage of average Debt - since Debt is projected to stay constant, due to this finance costs shrink as a proportion of Revenue, further boosting the pretax margin.
B11: Effective Tax Rate | C11: =Model!H38/Model!H37 -> 0.21607401 | D11: =-Model!I38/Model!I37 -> 0.062934714 | E11: =-Model!J38/Model!J37 -> 0.084337423 | F11: =-Model!K38/Model!K37 -> 0.10193757 | G11: =-Model!L38/Model!L37 -> 0.083692839 | H11: =-Model!M38/Model!M37 -> 0.088692839 | I11: =-Model!N38/Model!N37 -> 0.088692839 | J11: =-Model!O38/Model!O37 -> 0.093692839 | K11: =-Model!P38/Model!P37 -> 0.093692839 | ... Q11: =-Model!V38/Model!V37 -> 0.10869284 | T11: Tax Rate declined sharply from 21.61% in FY2022 to 6.29% in FY2023, indicating the impact of exceptional tax benefits such as deferred tax adjustments, tax credits or one-time tax reversals, before normalising to the 8.37-10.19% range by FY2026. During the forecast period, the Effective Tax Rate is assumed to increase by 0.50 percentage points every two years
B12: Net Profit Margin | C12: =Model!H39/Model!H26 -> 0.26250597 | D12: =Model!I39/Model!I26 -> 0.18422232 | E12: =Model!J39/Model!J26 -> 0.20238034 | F12: =Model!K39/Model!K26 -> 0.210739 | G12: =Model!L39/Model!L26 -> 0.20512183 | H12: =Model!M39/Model!M26 -> 0.21692439 | I12: =Model!N39/Model!N26 -> 0.22095289 | J12: =Model!O39/Model!O26 -> 0.22289896 | ... Q12: =Model!V39/Model!V26 -> 0.23007582 | T12: Net Profit Margin declined sharply from 26.25% in FY2022 to 18.42% in FY2023, primarily due to lower operating profitability despite a significantly lower effective tax rate. From FY2023 onwards, the net margin recovered steadily to 20.51% by FY2026. the margin recovers and then rises consistently every year of the forecast, from 21.69% in FY2027 to 23.01% by FY2036. This forecast-period improvement is the net result of the expanding Operating and Pretax margins (driven by D&A and Interest Expense growing slower than Revenue) being only partially offset by the gradually rising Effective Tax Rate assumption. This shows company remains highly profitable throughout the forecast period.
B13: Return on Assets | D13: =Model!I39/AVERAGE(Model!H60:I60) -> 0.2034627 | E13: =Model!J39/AVERAGE(Model!I60:J60) -> 0.22666246 | F13: =Model!K39/AVERAGE(Model!J60:K60) -> 0.23563952 | G13: =Model!L39/AVERAGE(Model!K60:L60) -> 0.21038077 | H13: =Model!M39/AVERAGE(Model!L60:M60) -> 0.21960007 | I13: =Model!N39/AVERAGE(Model!M60:N60) -> 0.21596477 | J13: =Model!O39/AVERAGE(Model!N60:O60) -> 0.2095341 | K13: =Model!P39/AVERAGE(Model!O60:P60) -> 0.20342455 | ... Q13: =Model!V39/AVERAGE(Model!U60:V60) -> 0.16036954 | T13: Return on Assets (ROA) rose from 20.35% in FY2023 to a peak of 23.56% in FY2025 on the back of improving Net Profit Margin and efficient asset utilisation, the company was generating nearly ₹24 of profit for every ₹100 of assets deployed, then declined to 21.04% in FY2026 and continues falling steadilyfrom 21.96% in FY2027 to 16.04% by FY2036. Because we assume no extraordinary dividends, no share buybacks, and no M&A, the free cash flow generated each year sits on the balance sheet as growing financial assets. The asset base therefore grows much faster than revenue or profit.
B14: Return on Equity | D14: =Model!I39/AVERAGE(Model!H75:I75) -> 0.28652894 | E14: =Model!J39/AVERAGE(Model!I75:J75) -> 0.30493886 | F14: =Model!K39/AVERAGE(Model!J75:K75) -> 0.31226828 | G14: =Model!L39/AVERAGE(Model!K75:L75) -> 0.27595349 | H14: =Model!M39/AVERAGE(Model!L75:M75) -> 0.28458502 | I14: =Model!N39/AVERAGE(Model!M75:N75) -> 0.27406455 | J14: =Model!O39/AVERAGE(Model!N75:O75) -> 0.26120041 | K14: =Model!P39/AVERAGE(Model!O75:P75) -> 0.24956903 | ... Q14: =Model!V39/AVERAGE(Model!U75:V75) -> 0.18404423 | T14: Return on Equity (ROE) increased from 28.65% in FY2023 to a peak of 31.23% in FY2025, driven by high net margins, reasonable asset efficiency, and very low financial leverage, then declines consistently from 27.60% in FY2026 to 18.40% by FY2036 almost 10 percentage points. With retained earnings expanding every year with no buybacks or extraordinary dividends, the equity expanding much faster than the Net Earnings, ROE compresses steadily, even though the underlying business remains highly profitable.
B16: Liquidity Ratios
B17: Current Ratio | C17: =SUM(Model!H47:H52)/SUM(Model!H65:H66) -> 1.6656246 | D17: =SUM(Model!I47:I52)/SUM(Model!I65:I66) -> 2.003054 | E17: =SUM(Model!J47:J52)/SUM(Model!J65:J66) -> 2.0846854 | F17: =SUM(Model!K47:K52)/SUM(Model!K65:K66) -> 2.4526955 | G17: =SUM(Model!L47:L52)/SUM(Model!L65:L66) -> 2.7623494 | H17: =SUM(Model!M47:M52)/SUM(Model!M65:M66) -> 3.2869343 | I17: =SUM(Model!N47:N52)/SUM(Model!N65:N66) -> 3.7868488 | J17: =SUM(Model!O47:O52)/SUM(Model!O65:O66) -> 4.2826552 | ... Q17: =SUM(Model!V47:V52)/SUM(Model!V65:V66) -> 7.8087835 | T17: The Current Ratio improved from 1.67x in FY2022 to 2.76x in FY2026, because the growth in current assets outpacing the growth in current liabilities, with the ratio above 1.50x throughout the historical period shows no liquidity risk at any point. Ratio then increases sharply every year of the forecast from 3.29x in FY2027 to reach 7.81x by FY2036, means company holds nearly ₹8 of current asset for every ₹1 of current liability. It arises because our model assumes all free cash flow accumulates on the balance sheet as current financial assets, year after year, with no extraordinary distributions or investments.
B18: Quick Ratio | C18: =(SUM(Model!H47:H52)-Model!H50)/SUM(Model!H65:H66) -> 1.1103683 | D18: =(SUM(Model!I47:I52)-Model!I50)/SUM(Model!I65:I66) -> 1.4924282 | E18: =(SUM(Model!J47:J52)-Model!J50)/SUM(Model!J65:J66) -> 1.6093068 | F18: =(SUM(Model!K47:K52)-Model!K50)/SUM(Model!K65:K66) -> 2.0168083 | G18: =(SUM(Model!L47:L52)-Model!L50)/SUM(Model!L65:L66) -> 2.1918937 | H18: =(SUM(Model!M47:M52)-Model!M50)/SUM(Model!M65:M66) -> 2.7407587 | I18: =(SUM(Model!N47:N52)-Model!N50)/SUM(Model!N65:N66) -> 3.2277276 | J18: =(SUM(Model!O47:O52)-Model!O50)/SUM(Model!O65:O66) -> 3.7120256 | ... Q18: =(SUM(Model!V47:V52)-Model!V50)/SUM(Model!V65:V66) -> 7.186069 | T18: The Quick Ratio (Current Assets minus inventory, divided by current liabilities) tracking the current ratio trend throughout the period with the gap between two ratios representing the inventory component. It rose from 1.11x in FY2022 to 2.19x in FY2026 and continues to climb in forecasting period to 7.19x by FY2036, the reason of dramatic rise is the same as current ratio- cash accumulation. Quick Ratio well above 1.00x is a positive signal during the audited years (it means the company can meet all short-term obligations without selling any inventory).
B20: Solvency Ratios
B21: Debt to Equity | C21: =Model!H68/(Model!H75+Model!H76) -> 0.13573561 | D21: =Model!I68/(Model!I75+Model!I76) -> 0.039134115 | E21: =Model!J68/(Model!J75+Model!J76) -> 0.038229088 | F21: =Model!K68/(Model!K75+Model!K76) -> 0.033337893 | G21: =Model!L68/(Model!L75+Model!L76) -> 0.055405757 | H21: =Model!M68/(Model!M75+Model!M76) -> 0.048263807 | I21: =Model!N68/(Model!N75+Model!N76) -> 0.042258502 | J21: =Model!O68/(Model!O75+Model!O76) -> 0.037232793 | ... Q21: =Model!V68/(Model!V75+Model!V76) -> 0.01794579 | T21: Debt to Equity ratio collapsed from 0.14x in FY2022 to just 0.04x in FY2023, reflecting a significant debt repayment or reclassification during that year. ticked up slightly to 0.06x in FY2026 (likely reflecting a fresh borrowing or lease liability addition), and then declines consistently every year of the forecast to 0.02x by FY2036. The projection-period decline is because Debt is assumed to remain constatnt throughout the forecast period, so the rapidly expanding Equity base (driven by retained profits) causes the ratio to fall steadily. Emami is effectively becoming a purely equity-financed company across our forecast horizon. An extremely low D/E ratio is often cited as a sign of financial strength, and it is, but it also means Emami foregoes the benefits of financial leverage.
B22: Debt to Assets | C22: =Model!H68/Model!H60 -> 0.092087258 | D22: =Model!I68/Model!I60 -> 0.029103636 | E22: =Model!J68/Model!J60 -> 0.028647694 | F22: =Model!K68/Model!K60 -> 0.025410419 | G22: =Model!L68/Model!L60 -> 0.042205795 | H22: =Model!M68/Model!M60 -> 0.037633926 | I22: =Model!N68/Model!N60 -> 0.033584204 | J22: =Model!O68/Model!O60 -> 0.030095752 | ... Q22: =Model!V68/Model!V60 -> 0.015695481 | T22: Debt to Assets ratio shows the same story as debt to equity, it fell sharply from 0.09x in FY2022 to 0.03x in FY2023 and the rose to 0.04x in FY2026, and then declines steadily to 0.02 by FY2036. The forecast-period decline reflects the same dynamic as above: Debt remains constant while Total Assets expand at a faster pace, so debt becomes an increasingly negligible component of the asset base, reducing financial risk further each year. The company maintains a conservative capital structure throughout the forecast period.
B23: Interest Coverage Ratio | C23: =Model!H34/(-Model!H35) -> 121.74437 | D23: =Model!I34/(-Model!I35) -> 83.273291 | E23: =Model!J34/(-Model!J35) -> 76.537626 | F23: =Model!K34/(-Model!K35) -> 90.704195 | G23: =Model!L34/(-Model!L35) -> 70.647799 | H23: =Model!M34/(-Model!M35) -> 46.342721 | I23: =Model!N34/(-Model!N35) -> 51.05877 | J23: =Model!O34/(-Model!O35) -> 55.663246 | ... Q23: =Model!V34/(-Model!V35) -> 83.98535 | T23: The Interest Coverage Ratio measures how many times Emami's EBIT covers its annual interest expense, a ratio above 3.00x is considered safe and above 10.00x as very strong. Emami's historical ICR has ranged from 70.65x to 121.74x, meaning the company earned between 71 and 122 times its interest obligation in any given year. reflecting a near debt free capital structure. Started at a very strong 121.74x in FY2022, eased to 70.65x in FY2026, it reflects slightly growing interest expense (higher finance charges as some debt was added in FY2026) and a mildly dipping EBIT in certain years. Ratio dipped further to a low of 46.34x in FY2027 and after that it recovers steadily to 83.99x by FY2036, as EBIT grows and interest obligation stays constant.
B25: Efficiency/Activity Ratios
B26: Asset Turnover ratio | D26: =Model!I26/AVERAGE(Model!H60:I60) -> 1.1044411 | E26: =Model!J26/AVERAGE(Model!I60:J60) -> 1.1199826 | F26: =Model!K26/AVERAGE(Model!J60:K60) -> 1.1181581 | G26: =Model!L26/AVERAGE(Model!K60:L60) -> 1.0256381 | H26: =Model!M26/AVERAGE(Model!L60:M60) -> 1.0123346 | I26: =Model!N26/AVERAGE(Model!M60:N60) -> 0.97742454 | J26: =Model!O26/AVERAGE(Model!N60:O60) -> 0.94004071 | K26: =Model!P26/AVERAGE(Model!O60:P60) -> 0.90233757 | ... Q26: =Model!V26/AVERAGE(Model!U60:V60) -> 0.6970291 | T26: Asset Turnover increased from 1.10x in FY2023 to 1.12x in FY2024 and declined to 1.03x in FY2026, ratio was stable and healthy throughout the historical period and generated approximately ₹1 of revenue for every ₹1 assets. Throughout the forecasting period it falled consistently to 0.70x by FY2036. This is the flip side of the Current and Cash Ratio trends: Total Assets grow faster than Revenue in the forecast period because of the build-up of cash, which do not directly generate sales. The operating business is not becoming less efficient — the asset base is being inflated by idle financial holdings.
B27: Fixed Asset Turnover | D27: =Model!I26/AVERAGE(Model!H55:I55) -> 5.0028018 | E27: =Model!J26/AVERAGE(Model!I55:J55) -> 5.6293355 | F27: =Model!K26/AVERAGE(Model!J55:K55) -> 6.3321982 | G27: =Model!L26/AVERAGE(Model!K55:L55) -> 6.5257103 | H27: =Model!M26/AVERAGE(Model!L55:M55) -> 7.2752187 | I27: =Model!N26/AVERAGE(Model!M55:N55) -> 8.0103927 | J27: =Model!O26/AVERAGE(Model!N55:O55) -> 8.7055176 | K27: =Model!P26/AVERAGE(Model!O55:P55) -> 9.3607414 | ... Q27: =Model!V26/AVERAGE(Model!U55:V55) -> 12.521875 | T27: The Fixed Asset Turnover Ratio increased steadily from 5.00x in FY2023 to 6.53x in FY2026 reflecting a significant improvement in the company's ability to generate revenue from its fixed asset base. Ratio is projected to rise further to 12.52x by FY2036. This reflects increasingly efficient utilization of fixed assets, with revenue growth significantly outpacing additions to the fixed asset base. A higher fixed asset turnover ratio is generally viewed positively as it demonstrates that the company is generating greater sales without requiring proportionate investments in fixed assets.
B28: Inventory Turnover | D28: =-Model!I27/AVERAGE(Model!H50:I50) -> 3.5042785 | E28: =-Model!J27/AVERAGE(Model!I50:J50) -> 3.5629766 | F28: =-Model!K27/AVERAGE(Model!J50:K50) -> 3.7821901 | G28: =-Model!L27/AVERAGE(Model!K50:L50) -> 3.2162048 | H28: =-Model!M27/AVERAGE(Model!L50:M50) -> 3.3521512 | I28: =-Model!N27/AVERAGE(Model!M50:N50) -> 3.4788597 | J28: =-Model!O27/AVERAGE(Model!N50:O50) -> 3.4680189 | K28: =-Model!P27/AVERAGE(Model!O50:P50) -> 3.4580353 | ... Q28: =-Model!V27/AVERAGE(Model!U50:V50) -> 3.4128747 | T28: The Inventory Turnover Ratio improved from 3.50x in FY2023 to 3.78x in FY2025, indicating more efficient inventory management and faster movement of products through the supply chain. Although the ratio temporarily declined to 3.22x in FY2026, suggesting that inventory levels increased at a faster pace than cost of goods sold. This decline may indicate inventory build-up, weaker demand, precautionary stocking, or slower inventory movement. it stabilizes around 3.35x–3.48x throughout the forecast period. This indicates a consistent inventory replenishment cycle and suggests that inventory levels are expected to remain aligned with sales growth, supporting efficient working capital management.
B29: Receivable Turnover | D29: =Model!I26/AVERAGE(Model!H49:I49) -> 9.260712 | E29: =Model!J26/AVERAGE(Model!I49:J49) -> 7.8741693 | F29: =Model!K26/AVERAGE(Model!J49:K49) -> 8.0574332 | G29: =Model!L26/AVERAGE(Model!K49:L49) -> 9.5128141 | H29: =Model!M26/AVERAGE(Model!L49:M49) -> 10.136383 | I29: =Model!N26/AVERAGE(Model!M49:N49) -> 9.121056 | J29: =Model!O26/AVERAGE(Model!N49:O49) -> 9.0926331 | K29: =Model!P26/AVERAGE(Model!O49:P49) -> 9.0664576 | ... Q29: =Model!V26/AVERAGE(Model!U49:V49) -> 8.9480531 | T29: The Receivables Turnover Ratio declined from 9.26x in FY2023 to 7.87x in FY2024, indicating slower collection of receivables and a greater amount of capital tied up in credit sales. The ratio subsequently improved to 8.06x in FY2025 and further increased to 9.51x in FY2026, indicating stronger collection efficiency and more effective credit management practices. Higher receivable turnover enhances liquidity, reduces credit risk, and improves cash flow generation. Thereafter, in forecasted period it increased slightly to 10.14x in FY2027 and then continues to decrease upto 8.95x by FY2036, while remaining at healthy levels. This suggests that the company is expected to maintain disciplined credit policies and stable collection practices in its long-term business expansion.
B30: Payable Turnover | D30: =-Model!I27/AVERAGE(Model!H65:I65) -> 2.9122838 | E30: =-Model!J27/AVERAGE(Model!I65:J65) -> 2.6651882 | F30: =-Model!K27/AVERAGE(Model!J65:K65) -> 2.6831082 | G30: =-Model!L27/AVERAGE(Model!K65:L65) -> 2.4938337 | H30: =-Model!M27/AVERAGE(Model!L65:M65) -> 2.7167015 | I30: =-Model!N27/AVERAGE(Model!M65:N65) -> 2.7312125 | J30: =-Model!O27/AVERAGE(Model!N65:O65) -> 2.7227016 | K30: =-Model!P27/AVERAGE(Model!O65:P65) -> 2.7148636 | ... Q30: =-Model!V27/AVERAGE(Model!U65:V65) -> 2.6794085 | T30: The Payables Turnover Ratio declined from 2.91x in FY2023 to 2.49x in FY2026, indicating that the company is taking longer to settle its obligations with suppliers. A lower payable turnover ratio generally implies extended credit periods, which can be beneficial for cash flow management as the company retains cash for a longer duration. The ratio subsequently stabilizes around 2.68x–2.73x over the forecast period, indicating a balanced approach toward supplier payments. This stability suggests that the company is expected to maintain consistent relationships with vendors while optimizing working capital requirements.
B31: Cash Conversion Cycle (Days) | C31: =Model!H17+Model!H18-Model!H19 -> 19.363166 | D31: =Model!I17+Model!I18-Model!I19 -> 17.619869 | E31: =Model!J17+Model!J18-Model!J19 -> 9.1551197 | F31: =Model!K17+Model!K18-Model!K19 -> 4.2760322 | G31: =Model!L17+Model!L18-Model!L19 -> 8.3017879 | H31: =Model!M17+Model!M18-Model!M19 -> 11.743195 | I31: =Model!N17+Model!N18-Model!N19 -> 11.743195 | J31: =Model!O17+Model!O18-Model!O19 -> 11.743195 | ... Q31: =Model!V17+Model!V18-Model!V19 -> 11.743195 | T31: The Cash Conversion Cycle improved significantly from 19.36 days in FY2022 to 4.28 days in FY2025, reflecting substantial enhancement in working capital efficiency through faster inventory turnover, improved receivable collections, and effective management of payables. A CCC of 4.28 days means Emami was converting raw material investment into customer cash in just 4.28 days on average in FY2025. The ratio rise slighlty 8.30 days in FY2026 and our model forecasts Days ratios at their five-year historical average producing a constant CCC of 11.74 days from FY2027 onwards, it remains substantially below historical levels, indicating a structurally efficient operating cycle and strong cash generation capability. The consistently low CCC highlights the company's ability to convert operating profits into cash with minimal working capital investment.

Sheet Equity Beta
A1: Emami Limited
A2: Equity Beta
D5: Date | E5: Emami | F5: Change | G5: Index Close Price | H5: Change
E6: Limited | F6: % | H6: % | J6: Covariance | K6: =_xlfn.COVARIANCE.S(F7:F502,H7:H502) -> 4.7548657e-05
D7: 46206 | E7: 420.05 | F7: =E7/E8-1 -> 0.0076766223 | G7: 24270.85 | H7: =G7/G8-1 -> 0.0039357702 | J7: Variance | K7: =_xlfn.VAR.S(H7:H502) -> 7.0714928e-05
D8: 46205 | E8: 416.85 | F8: =E8/E9-1 -> 0.0051844707 | G8: 24175.7 | H8: =G8/G9-1 -> 0.0070753587 | J8: Beta | K8: =K6/K7 -> 0.67239914
D9: 46204 | E9: 414.7 | F9: =E9/E10-1 -> 0.025723473 | G9: 24005.85 | H9: =G9/G10-1 -> 0.0058703372
D10: 46203 | E10: 404.3 | F10: =E10/E11-1 -> -0.010402643 | G10: 23865.75 | H10: =G10/G11-1 -> -0.0033616955
D11: 46202 | E11: 408.55 | F11: =E11/E12-1 -> 0.029222824 | G11: 23946.25 | H11: =G11/G12-1 -> -0.0045622714
D12: 46198 | E12: 396.95 | F12: =E12/E13-1 -> -0.01720723 | G12: 24056 | H12: =G12/G13-1 -> 0.0014299601
D13: 46197 | E13: 403.9 | F13: =E13/E14-1 -> 0.0066043614 | G13: 24021.65 | H13: =G13/G14-1 -> 0.0082920236
D14: 46196 | E14: 401.25 | F14: =E14/E15-1 -> -0.013643068 | G14: 23824.1 | H14: =G14/G15-1 -> -0.011567073
D15: 46195 | E15: 406.8 | F15: =E15/E16-1 -> -0.016203144 | G15: 24102.9 | H15: =G15/G16-1 -> 0.0037396255
D16: 46192 | E16: 413.5 | F16: =E16/E17-1 -> 0.03284626 | G16: 24013.1 | H16: =G16/G17-1 -> -0.0064093016
D17: 46191 | E17: 400.35 | F17: =E17/E18-1 -> 0.00049981257 | G17: 24168 | H17: =G17/G18-1 -> 0.0034169653
D18: 46190 | E18: 400.15 | F18: =E18/E19-1 -> 0 | G18: 24085.7 | H18: =G18/G19-1 -> 0.0040247362
D19: 46189 | E19: 400.15 | F19: =E19/E20-1 -> 0.0084425403 | G19: 23989.15 | H19: =G19/G20-1 -> 0.0056699324
D20: 46188 | E20: 396.8 | F20: =E20/E21-1 -> 0.015353122 | G20: 23853.9 | H20: =G20/G21-1 -> 0.009778647
... D502: 45476 | E502: 736.4 | F502: =E502/E503-1 -> 0.018041059 | G502: 24286.5 | H502: =G502/G503-1 -> 0.0067422903
E503: 723.35 | G503: 24123.85

Sheet Market Returns
A1: Emami Limited
A2: Equity Market Returns
D5: Date | E5: Index Close Price | F5: Change
F6: %
D7: 46206 | E7: 24270.85 | F7: =E14/E15-1 -> -0.011567073 | H7: Index | I7: Nifty 50
D8: 46205 | E8: 24175.7 | F8: =E15/E16-1 -> 0.0037396255
D9: 46204 | E9: 24005.85 | F9: =E16/E17-1 -> -0.0064093016 | H9: Year Frac | I9: =YEARFRAC(D2483,D7) -> 9.9972222
D10: 46203 | E10: 23865.75 | F10: =E17/E18-1 -> 0.0034169653
D11: 46202 | E11: 23946.25 | F11: =E18/E19-1 -> 0.0040247362 | H11: Market Return | I11: =_xlfn.RRI(I9,E2483,E7) -> 0.1123595
D12: 46198 | E12: 24056 | F12: =E19/E20-1 -> 0.0056699324
D13: 46197 | E13: 24021.65 | F13: =E20/E21-1 -> 0.009778647
D14: 46196 | E14: 23824.1 | F14: =E21/E22-1 -> 0.019916586
D15: 46195 | E15: 24102.9 | F15: =E22/E23-1 -> -0.0022980881
D16: 46192 | E16: 24013.1 | F16: =E23/E24-1 -> -0.0011681389
D17: 46191 | E17: 24168 | F17: =E24/E25-1 -> 0.0051507157
D18: 46190 | E18: 24085.7 | F18: =E25/E26-1 -> -0.010429372
D19: 46189 | E19: 23989.15 | F19: =E26/E27-1 -> -0.0021288362
D20: 46188 | E20: 23853.9 | F20: =E20/E21-1 -> 0.009778647
D21: 46185 | E21: 23622.9 | F21: =E21/E22-1 -> 0.019916586
D22: 46184 | E22: 23161.6 | F22: =E22/E23-1 -> -0.0022980881
D23: 46183 | E23: 23214.95 | F23: =E23/E24-1 -> -0.0011681389
D24: 46182 | E24: 23242.1 | F24: =E24/E25-1 -> 0.0051507157
D25: 46181 | E25: 23123 | F25: =E25/E26-1 -> -0.010429372
D26: 46178 | E26: 23366.7 | F26: =E26/E27-1 -> -0.0021288362
D27: 46177 | E27: 23416.55 | F27: =E27/E28-1 -> 0.00046783676
D28: 46176 | E28: 23405.6 | F28: =E28/E29-1 -> -0.0033193448
D29: 46175 | E29: 23483.55 | F29: =E29/E30-1 -> 0.0043173129
D30: 46174 | E30: 23382.6 | F30: =E30/E31-1 -> -0.0070134089
D31: 46171 | E31: 23547.75 | F31: =E31/E32-1 -> -0.01503316
... D2483: 42555 | E2483: 8370.7 | F2483: =E2483/E2484-1 -> 0.0050850409
E2484: 8328.35

Sheet DCF Valuation
A1: Emami Limited
A2: DCF Valuation
A4: WACC Calculations
C6: Capital Structure
D7: Market Cap | F7: =Assumptions!D20 -> 1833518.2
D8: Total Debt | F8: =Model!L68 -> 16192
D9: Total | F9: =SUM(F7:F8) -> 1849710.2
C11: Weightage
D12: Equity | F12: =F7/F9 -> 0.9912462
D13: Debt | F13: =F8/F9 -> 0.0087538035
F14: =SUM(F12:F13) -> 1
C16: Cost of Debt
D17: Pre Tax Cost of Debt | F17: =Assumptions!D28 -> 0.124
D18: Tax Rate | F18: =Model!M15 -> 0.088692839
D19: After Tax Cost of Debt | F19: =F17*(1-F18) -> 0.11300209
C21: Cost of Equity
D22: Risk Free Rate | F22: =Assumptions!D27 -> 0.06707
D23: Equity Market Return | F23: ='Market Returns'!I11 -> 0.1123595
D24: Equity Risk Premium | F24: =F23-F22 -> 0.045289496
D25: Equity Beta | F25: ='Equity Beta'!K8 -> 0.67239914
D26: Cost of Equity | F26: =F22+(F24*F25) -> 0.097522618
D28: WACC | F28: =(F19*F13)+(F26*F12) -> 0.097658123
T30: ₹ in Lacs
A31: Unlevered FCFF
D32: Particulars | F32: =Model!H2 -> 2022 | G32: =Model!I2 -> 2023 | H32: =Model!J2 -> 2024 | I32: =Model!K2 -> 2025 | J32: =Model!L2 -> 2026 | K32: =Model!M2 -> 2027 | L32: =Model!N2 -> 2028 | M32: =Model!O2 -> 2029 | ... T32: =Model!V2 -> 2036
D34: EBIT | F34: =Model!H34 -> 61759.7 | G34: =Model!I34 -> 61550.62 | H34: =Model!J34 -> 76363.12 | I34: =Model!K34 -> 84689.6 | J34: =Model!L34 -> 78631 | K34: =Model!M34 -> 93013.26 | L34: =Model!N34 -> 102478.72 | M34: =Model!O34 -> 111720.24 | ... T34: =Model!V34 -> 168564.79
D35: Less: Tax | F35: =Model!H38 -> 14866 | G35: =Model!I38 -> -4213.79 | H35: =Model!J38 -> -6669.68 | I35: =Model!K38 -> -9111.82 | J35: =Model!L38 -> -7081 | K35: =Model!M38 -> -8697.4942 | L35: =Model!N38 -> -9588.5551 | M35: =Model!O38 -> -11048.891 | ... T35: =Model!V38 -> -19390.385
D36: Add: Depreciation & Amortisation | F36: =-Model!H33 -> 33477.79 | G36: =-Model!I33 -> 24724.9 | H36: =-Model!J33 -> 18590.59 | I36: =-Model!K33 -> 17821.4 | J36: =-Model!L33 -> 17734 | K36: =-Model!M33 -> 17524.948 | L36: =-Model!N33 -> 17162.312 | M36: =-Model!O33 -> 16935.771 | ... T36: =-Model!V33 -> 16870.478
D37: Less: Capex | F37: =-Model!H129 -> 0 | G37: =-Model!I129 -> -19427.73 | H37: =-Model!J129 -> -14858.01 | I37: =-Model!K129 -> -14742.55 | J37: =-Model!L129 -> -16335.56 | K37: =-Model!M129 -> -16340.963 | L37: =-Model!N129 -> -16422.667 | M37: =-Model!O129 -> -16504.781 | ... T37: =-Model!V129 -> -17091.186
D38: Change in Working Capital | F38: =Model!H124 -> -16909.92 | G38: =Model!I124 -> -1124.22 | H38: =Model!J124 -> -3374.66 | I38: =Model!K124 -> 4611.72 | J38: =Model!L124 -> 858 | K38: =Model!M124 -> -9394.9315 | L38: =Model!N124 -> -2962.7827 | M38: =Model!O124 -> -2934.1926 | ... T38: =Model!V124 -> -2347.0526
D40: Unlevered FCFF | F40: =SUM(F34:F39) -> 93193.57 | G40: =SUM(G34:G39) -> 61509.78 | H40: =SUM(H34:H39) -> 70051.36 | I40: =SUM(I34:I39) -> 83268.35 | J40: =SUM(J34:J39) -> 73806.44 | K40: =SUM(K34:K39) -> 76104.82 | L40: =SUM(L34:L39) -> 90667.025 | M40: =SUM(M34:M39) -> 98168.147 | ... T40: =SUM(T34:T39) -> 146606.65
C45: Terminal Value
D46: Perpetual Growth Rate | F46: =Assumptions!D26 -> 0.04
D47: EV/EBITDA Multiple | F47: ='Comps Valuation'!T21 -> 32.56334
D49: Terminal Value (Perpetual Growth Rate) | F49: =T40*(1+F46)/(F28-F46) -> 2644396.1
D50: Terminal Value (EV/EBITDA) | F50: =(T34+T36)*F47 -> 6038391.9
D51: Average | F51: =AVERAGE(F49:F50) -> 4341394
C53: Intrinsic Value
D54: Sum of PV of Cashflows | F54: =NPV(F28,K40:T40) -> 680381.61
D55: PV of Terminal Value | F55: =PV(F28,COUNT(K32:T32),0,-F51) -> 1709850.9
...

Sheet Comps Inputs
A1: Emami Limited
A2: COMPS Inputs Data
L5: Source: NSE, Company Annual Reports
D6: Company Name | E6: Ticker
H7: Price | I7: Shares | J7: Debt | K7: Cash & Cash Equivalents | L7: Sales | M7: EBITDA | N7: Earnings
H8: (₹ per share) | I8: (Lacs) | J8: (₹ in Lacs) | K8: (₹ in Lacs) | L8: (₹ in Lacs) | M8: (₹ in Lacs) | N8: (₹ in Lacs)
D9: Emami Limited | E9: EMAMILTD | H9: =Assumptions!D11 -> 420.05 | I9: =Assumptions!D17 -> 4365 | J9: =Model!L68 -> 16192 | K9: =Model!L47+Model!L48+Model!L51 -> 97779 | L9: =Model!L26 -> 377951 | M9: =Model!L32 -> 96365 | N9: =Model!L39 -> 77526
D10: P & G Hygine | E10: PGHH | H10: 8902 | I10: 324.6 | J10: 87 | K10: 55702 | L10: 429042 | M10: 117104 | N10: 85650
D11: Colgate-Palmolive | E11: COLPAL | H11: 2047 | I11: 2720 | J11: 4741 | K11: 142604 | L11: 603504 | M11: 186966 | N11: 132531
D12: Dabur India | E12: DABUR | H12: 444.35 | I12: 17723 | J12: 128732 | K12: 19937 | L12: 1319257 | M12: 245184 | N12: 186869
D13: Godrej Consumer Product Limited | E13: GODREJCP | H13: 1076.9 | I13: 10232 | J13: 441581 | K13: 100541 | L13: 1517790 | M13: 315624 | N13: 186147
D14: Honasa Consumer | E14: HONASA | H14: 461.75 | I14: 3254 | J14: 13534.6 | K14: 11922.4 | L14: 239194.2 | M14: 23615.6 | N14: 20019
D15: Gillette India | E15: GILLETTE | H15: 7610.5 | I15: 326 | J15: 2 | K15: 26926 | L15: 309953 | M15: 94305 | N15: 65431
D16: Bajaj Consumer Care Ltd | E16: BAJAJCON | H16: 616.2 | I16: 1306 | J16: 1579.73 | K16: 2170.73 | L16: 116471.34 | M16: 22092.08 | N16: 19018.1

Sheet Comps Valuation
A1: Emami Limited
A2: COMPS Valuation
D7: Company Name | E7: Ticker | H7: Market Data | O7: Financial Data | S7: Valuation
H8: Price | I8: Shares | J8: Market Cap | K8: Debt | L8: Cash & Cash Equivalents | M8: EV | O8: Sales | P8: EBITDA | Q8: Earnings | S8: EV/Sales | T8: EV/EBITDA | U8: P/E
H9: (₹ per share) | I9: (Lacs) | J9: (₹ in Lacs) | K9: (₹ in Lacs) | L9: (₹ in Lacs) | M9: (₹ in Lacs) | O9: (₹ in Lacs) | P9: (₹ in Lacs) | Q9: (₹ in Lacs) | S9: x | T9: x | U9: x
D10: P & G Hygine | E10: PGHH | H10: ='Comps Inputs'!H10 -> 8902 | I10: ='Comps Inputs'!I10 -> 324.6 | J10: =H10*I10 -> 2889589.2 | K10: ='Comps Inputs'!J10 -> 87 | L10: ='Comps Inputs'!K10 -> 55702 | M10: =J10+K10-L10 -> 2833974.2 | O10: ='Comps Inputs'!L10 -> 429042 | P10: ='Comps Inputs'!M10 -> 117104 | Q10: ='Comps Inputs'!N10 -> 85650 | S10: =M10/O10 -> 6.6053538 | T10: =M10/P10 -> 24.20049 | U10: =J10/Q10 -> 33.737177
D11: Colgate-Palmolive | E11: COLPAL | H11: ='Comps Inputs'!H11 -> 2047 | I11: ='Comps Inputs'!I11 -> 2720 | J11: =H11*I11 -> 5567840 | K11: ='Comps Inputs'!J11 -> 4741 | L11: ='Comps Inputs'!K11 -> 142604 | M11: =J11+K11-L11 -> 5429977 | O11: ='Comps Inputs'!L11 -> 603504 | P11: ='Comps Inputs'!M11 -> 186966 | Q11: ='Comps Inputs'!N11 -> 132531 | S11: =M11/O11 -> 8.9974168 | T11: =M11/P11 -> 29.042591 | U11: =J11/Q11 -> 42.011605
D12: Dabur India | E12: DABUR | H12: ='Comps Inputs'!H12 -> 444.35 | I12: ='Comps Inputs'!I12 -> 17723 | J12: =H12*I12 -> 7875215.1 | K12: ='Comps Inputs'!J12 -> 128732 | L12: ='Comps Inputs'!K12 -> 19937 | M12: =J12+K12-L12 -> 7984010.1 | O12: ='Comps Inputs'!L12 -> 1319257 | P12: ='Comps Inputs'!M12 -> 245184 | Q12: ='Comps Inputs'!N12 -> 186869 | S12: =M12/O12 -> 6.0518989 | T12: =M12/P12 -> 32.56334 | U12: =J12/Q12 -> 42.142972
D13: Godrej Consumer Product Limited | E13: GODREJCP | H13: ='Comps Inputs'!H13 -> 1076.9 | I13: ='Comps Inputs'!I13 -> 10232 | J13: =H13*I13 -> 11018841 | K13: ='Comps Inputs'!J13 -> 441581 | L13: ='Comps Inputs'!K13 -> 100541 | M13: =J13+K13-L13 -> 11359881 | O13: ='Comps Inputs'!L13 -> 1517790 | P13: ='Comps Inputs'!M13 -> 315624 | Q13: ='Comps Inputs'!N13 -> 186147 | S13: =M13/O13 -> 7.4844878 | T13: =M13/P13 -> 35.991816 | U13: =J13/Q13 -> 59.194297
D14: Honasa Consumer | E14: HONASA | H14: ='Comps Inputs'!H14 -> 461.75 | I14: ='Comps Inputs'!I14 -> 3254 | J14: =H14*I14 -> 1502534.5 | K14: ='Comps Inputs'!J14 -> 13534.6 | L14: ='Comps Inputs'!K14 -> 11922.4 | M14: =J14+K14-L14 -> 1504146.7 | O14: ='Comps Inputs'!L14 -> 239194.2 | P14: ='Comps Inputs'!M14 -> 23615.6 | Q14: ='Comps Inputs'!N14 -> 20019 | S14: =M14/O14 -> 6.2883912 | T14: =M14/P14 -> 63.692928 | U14: =J14/Q14 -> 75.055422
